2021-07-24 01:32:49,598, ERROR, __main__, Бот упал с ошибкой: list index out of range
Traceback (most recent call last):
  File "/mnt/c/Dev/api_sp1_bot-1/homework.py", line 63, in main
    homework = homeworks['homeworks'][0]
IndexError: list index out of range
2021-07-24 01:35:44,460, DEBUG, __main__, Бот запущен
2021-07-24 01:35:44,635, ERROR, __main__, Бот упал с ошибкой: list index out of range
Traceback (most recent call last):
  File "/mnt/c/Dev/api_sp1_bot-1/homework.py", line 63, in main
    homework = homeworks['homeworks'][0]
IndexError: list index out of range
2021-07-24 01:35:50,019, DEBUG, __main__, Бот запущен
2021-07-24 01:35:50,292, ERROR, __main__, Бот упал с ошибкой: list index out of range
Traceback (most recent call last):
  File "/mnt/c/Dev/api_sp1_bot-1/homework.py", line 63, in main
    homework = homeworks['homeworks'][0]
IndexError: list index out of range
