2021-07-24 01:32:38,345, DEBUG, __main__, Бот запущен
2021-07-24 01:32:38,614, ERROR, __main__, Бот упал с ошибкой: list index out of range
Traceback (most recent call last):
  File "/mnt/c/Dev/api_sp1_bot-1/homework.py", line 63, in main
    homework = homeworks['homeworks'][0]
IndexError: list index out of range
2021-07-24 01:32:43,954, DEBUG, __main__, Бот запущен
2021-07-24 01:32:44,312, ERROR, __main__, Бот упал с ошибкой: list index out of range
Traceback (most recent call last):
  File "/mnt/c/Dev/api_sp1_bot-1/homework.py", line 63, in main
    homework = homeworks['homeworks'][0]
IndexError: list index out of range
2021-07-24 01:32:49,390, DEBUG, __main__, Бот запущен
